Workbook

Sheet Cases
A1: formula | B1: result
A2: =SUM(Data!A1:A10) | B2: {=SUM(Data!A1:A10)} -> 55
A3: =SUM(Data!B1:B10) | B3: {=SUM(Data!B1:B10)} -> #N/A
A4: =SUM(1,"2",TRUE) | B4: {=SUM(1,"2",TRUE)} -> 4
A5: =SUMPRODUCT(Data!A1:A5,Data!A6:A10) | B5: {=SUMPRODUCT(Data!A1:A5,Data!A6:A10)} -> 130
A6: =PRODUCT(Data!A1:A5) | B6: {=PRODUCT(Data!A1:A5)} -> 120
A7: =0.1+0.2 | B7: {=0.1+0.2} -> 0.3
A8: =0.1+0.2=0.3 | B8: {=0.1+0.2=0.3} -> TRUE
A9: =1/0 | B9: {=1/0} -> #DIV/0!
A10: =-7/2 | B10: {=-7/2} -> -3.5
A11: =MOD(-7,3) | B11: {=MOD(-7,3)} -> 2
A12: =MOD(7,-3) | B12: {=MOD(7,-3)} -> -2
A13: =INT(-2.5) | B13: {=INT(-2.5)} -> -3
A14: =TRUNC(-2.5) | B14: {=TRUNC(-2.5)} -> -2
A15: =ROUND(2.5,0) | B15: {=ROUND(2.5,0)} -> 3
A16: =ROUND(-2.5,0) | B16: {=ROUND(-2.5,0)} -> -3
A17: =ROUND(1.005,2) | B17: {=ROUND(1.005,2)} -> 1.01
A18: =ROUNDUP(1.21,1) | B18: {=ROUNDUP(1.21,1)} -> 1.3
A19: =ROUNDDOWN(-1.29,1) | B19: {=ROUNDDOWN(-1.29,1)} -> -1.2
A20: =MROUND(10,3) | B20: {=MROUND(10,3)} -> 9
A21: =CEILING(2.1,1) | B21: {=CEILING(2.1,1)} -> 3
A22: =FLOOR.MATH(-2.5) | B22: {=_xlfn.FLOOR.MATH(-2.5)} -> -3
A23: =CEILING.MATH(-2.5) | B23: {=_xlfn.CEILING.MATH(-2.5)} -> -2
A24: =POWER(2,0.5) | B24: {=POWER(2,0.5)} -> 1.4142136
A25: =SQRT(-1) | B25: {=SQRT(-1)} -> #NUM!
A26: =2^10 | B26: {=2^10} -> 1024
A27: =-2^2 | B27: {=-2^2} -> 4
A28: =EXP(1) | B28: {=EXP(1)} -> 2.7182818
A29: =LN(0) | B29: {=LN(0)} -> #NUM!
A30: =LOG(1000) | B30: {=LOG(1000)} -> 3
A31: =LOG10(0.001) | B31: {=LOG10(0.001)} -> -3
A32: =FACT(20) | B32: {=FACT(20)} -> 2.432902e+18
A33: =FACT(170) | B33: {=FACT(170)} -> 7.2574156e+306
A34: =FACT(171) | B34: {=FACT(171)} -> #NUM!
A35: =COMBIN(10,3) | B35: {=COMBIN(10,3)} -> 120
A36: =GCD(12,18) | B36: {=GCD(12,18)} -> 6
A37: =LCM(4,6) | B37: {=LCM(4,6)} -> 12
A38: =ABS(-0) | B38: {=ABS(0)} -> 0
A39: =SIGN(-0.001) | B39: {=SIGN(-0.001)} -> -1
A40: =PI() | B40: {=PI()} -> 3.1415927
...

Sheet Data
A1: 1 | B1: 5 | C1: apple | D1: 10 | E1: 1 | F1: one | G1: 59 | H1: 2.5
A2: 2 | B2: abc | C2: Banana | D2: 20 | E2: 3 | F2: three | G2: 61 | H2: 3.1
A3: 3 | B3: TRUE | C3: cherry | D3: 30 | E3: 5 | F3: five | G3: 45351 | H3: 4.7
A4: 4 | C4: apple | D4: 40 | E4: 7 | F4: seven | G4: 45657 | H4: 1.2
A5: 5 | B5: =NA() -> #N/A | C5: date | D5: 50 | E5: 9 | F5: nine | H5: 9.9
A6: 6 | B6: 45000 | H6: 3.3
A7: 7 | B7: 12 | H7: 7.4
A8: 8 | B8: 0 | H8: 5.5
A9: 9 | B9: -3.5
A10: 10 | B10: =""
