Workbook

Sheet Cases
A1: formula | B1: result
A2: =VALUETOTEXT("abc",1) | B2: {=_xlfn.VALUETOTEXT("abc",1)} -> "abc"
A3: =VALUETOTEXT(12.5) | B3: {=_xlfn.VALUETOTEXT(12.5)} -> 12.5
A4: =ARRAYTOTEXT({1,"a";TRUE,2}) | B4: {=_xlfn.ARRAYTOTEXT({1,"a";TRUE,2})} -> 1, a, TRUE, 2
A5: =ARRAYTOTEXT({1,"a";TRUE,2},1) | B5: {=_xlfn.ARRAYTOTEXT({1,"a";TRUE,2},1)} -> {1,"a";TRUE,2}
A6: =BAHTTEXT(1234.56) | B6: {=BAHTTEXT(1234.56)} -> หนึ่งพันสองร้อยสามสิบสี่บาทห้าสิบหกสตางค์
A7: =BAHTTEXT(21) | B7: {=BAHTTEXT(21)} -> ยี่สิบเอ็ดบาทถ้วน
A8: =BAHTTEXT(0) | B8: {=BAHTTEXT(0)} -> ศูนย์บาทถ้วน
A9: =BAHTTEXT(1000000) | B9: {=BAHTTEXT(1000000)} -> หนึ่งล้านบาทถ้วน
A10: =BAHTTEXT(101) | B10: {=BAHTTEXT(101)} -> หนึ่งร้อยเอ็ดบาทถ้วน
A11: =BAHTTEXT(11.01) | B11: {=BAHTTEXT(11.01)} -> สิบเอ็ดบาทหนึ่งสตางค์
A12: =REGEXTEST("abc123","[0-9]+") | B12: {=_xlfn.REGEXTEST("abc123","[0-9]+")} -> TRUE
A13: =REGEXTEST("ABC","abc",1) | B13: {=_xlfn.REGEXTEST("ABC","abc",1)} -> TRUE
A14: =REGEXEXTRACT("abc123def456","[0-9]+") | B14: {=_xlfn.REGEXEXTRACT("abc123def456","[0-9]+")} -> 123
A15: =REGEXEXTRACT("abc123def456","[0-9]+",1) | B15: {=_xlfn.REGEXEXTRACT("abc123def456","[0-9]+",1)} -> 123 | C15: 456
A16: =REGEXEXTRACT("John Smith","(\w+) (\w+)",2) | B16: {=_xlfn.REGEXEXTRACT("John Smith","(\w+) (\w+)",2)} -> John | C16: Smith
A17: =REGEXREPLACE("abc123","[0-9]","#") | B17: {=_xlfn.REGEXREPLACE("abc123","[0-9]","#")} -> abc###
A18: =REGEXREPLACE("a1b2c3","[0-9]","#",2) | B18: {=_xlfn.REGEXREPLACE("a1b2c3","[0-9]","#",2)} -> a1b#c3
A19: =CELL("address",Data!C3) | B19: {=CELL("address",Data!C3)} -> '[4-misc.xlsx]Data'!$C$3
A20: =CELL("col",Data!C3) | B20: {=CELL("col",Data!C3)} -> 3
A21: =CELL("contents",Data!A2) | B21: {=CELL("contents",Data!A2)} -> 2
A22: =CELL("type",Data!C1) | B22: {=CELL("type",Data!C1)} -> l
A23: =INFO("recalc") | B23: {=INFO("recalc")} -> Automatic
A24: =PERCENTOF(Data!A1:A3,Data!A1:A10) | B24: {=_xlfn.PERCENTOF(Data!A1:A3,Data!A1:A10)} -> 0.10909091
A25: =GROUPBY(Data!J2:J6,Data!K2:K6,SUM) | B25: {=_xlfn.GROUPBY(Data!J2:J6,Data!K2:K6,_xleta.SUM)} -> East | C25: 175
B26: North | C26: 300
B27: West | C27: 375
B28: Total | C28: 850
A29: =GROUPBY(Data!J2:J6,Data!K2:K6,AVERAGE,0,0) | B29: {=_xlfn.GROUPBY(Data!J2:J6,Data!K2:K6,_xleta.AVERAGE,0,0)} -> East | C29: 87.5
B30: North | C30: 300
B31: West | C31: 187.5
A32: =PIVOTBY(Data!J2:J6,Data!I2:I6,Data!K2:K6,SUM) | B32: {=_xlfn.PIVOTBY(Data!J2:J6,Data!I2:I6,Data!K2:K6,_xleta.SUM)} | C32: apple | D32: fig | E32: kiwi | F32: pear | G32: plum | H32: Total
B33: East | C33: 100 | D33: 75 | H33: 175
B34: North | E34: 300 | H34: 300
B35: West | F35: 250 | G35: 125 | H35: 375
B36: Total | C36: 100 | D36: 75 | E36: 300 | F36: 250 | G36: 125 | H36: 850
A37: =TRIMRANGE(Data!A1:A20) | B37: {=_xlfn.TRIMRANGE(Data!A1:A20)} -> 1
B38: 2
B39: 3
B40: 4
...

Sheet Data
A1: 1 | B1: 5 | C1: apple | D1: 10 | E1: 1 | F1: one | G1: 59 | H1: 2.5 | I1: Name | J1: Region | K1: Sales | L1: Region | M1: Sales | N1: Region | O1: Sales | P1: 5 | Q1: 2
A2: 2 | B2: abc | C2: Banana | D2: 20 | E2: 3 | F2: three | G2: 61 | H2: 3.1 | I2: apple | J2: East | K2: 100 | L2: East | M2: >90 | N2: West | O2: >200 | P2: 3 | Q2: 7
A3: 3 | B3: TRUE | C3: cherry | D3: 30 | E3: 5 | F3: five | G3: 45351 | H3: 4.7 | I3: pear | J3: West | K3: 250 | P3: 8 | Q3: 1
A4: 4 | C4: apple | D4: 40 | E4: 7 | F4: seven | G4: 45657 | H4: 1.2 | I4: fig | J4: East | K4: 75 | P4: 1 | Q4: 8
A5: 5 | B5: =NA() -> #N/A | C5: date | D5: 50 | E5: 9 | F5: nine | H5: 9.9 | I5: kiwi | J5: North | K5: 300 | P5: 9 | Q5: 2
A6: 6 | B6: 45000 | H6: 3.3 | I6: plum | J6: West | K6: 125 | P6: 2 | Q6: 8
A7: 7 | B7: 12 | H7: 7.4 | P7: 7 | Q7: 1
A8: 8 | B8: 0 | H8: 5.5 | P8: 4 | Q8: 8
A9: 9 | B9: -3.5
A10: 10 | B10: =""
